Workbook

Sheet MAIN
A1: Weight Start (g) | B1: Feed Rate (%)
A2: 2 | B2: 8
A3: 3 | B3: 7
A4: 5 | B4: 5.5
A5: 10 | B5: 4.5
A6: 15 | B6: 3.8
A7: 20 | B7: 3.2
A8: 25 | B8: 2.9
A9: 30 | B9: 2.5
A10: 35 | B10: 2.3

Sheet T1_Stocking
A1: Date | B1: Sector | C1: Pond ID | D1: Area (ha) | E1: Stocking Density (pcs/m2) | F1: Total Stocked (pcs) | G1: Stocking ABW (g) | H1: Initial Biomass (kg)
A2: 46023 | B2: A | C2: A1 | D2: 9.37 | E2: 45 | F2: 4218543 | G2: 3.22 | H2: 13599.34
A3: 46023 | B3: A | C3: A2 | D3: 9.95 | E3: 45 | F3: 4477821 | G3: 2.28 | H3: 10204.9
A4: 46023 | B4: A | C4: A3 | D4: 9.73 | E4: 45 | F4: 4379397 | G4: 2.58 | H4: 11317.63
A5: 46023 | B5: A | C5: A4 | D5: 9.6 | E5: 45 | F5: 4319396 | G5: 2.73 | H5: 11803.72
A6: 46023 | B6: A | C6: A5 | D6: 9.16 | E6: 45 | F6: 4120208 | G6: 2.91 | H6: 11998.62
A7: 46024 | B7: B | C7: B1 | D7: 9.16 | E7: 45 | F7: 4120198 | G7: 3.57 | H7: 14710.56
A8: 46024 | B8: B | C8: B2 | D8: 9.06 | E8: 45 | F8: 4076138 | G8: 2.4 | H8: 9780.07
A9: 46024 | B9: B | C9: B3 | D9: 9.87 | E9: 45 | F9: 4439779 | G9: 3.03 | H9: 13445.73
A10: 46024 | B10: B | C10: B4 | D10: 9.6 | E10: 45 | F10: 4320502 | G10: 3.18 | H10: 13760.06
A11: 46024 | B11: B | C11: B5 | D11: 9.71 | E11: 45 | F11: 4368633 | G11: 2.09 | H11: 9143.11
A12: 46025 | B12: C | C12: C1 | D12: 9.02 | E12: 45 | F12: 4059263 | G12: 3.22 | H12: 13050.89
A13: 46025 | B13: C | C13: C2 | D13: 9.97 | E13: 45 | F13: 4486459 | G13: 2.34 | H13: 10503.02
... A21: 46026 | B21: D | C21: D5 | D21: 9.29 | E21: 45 | F21: 4181053 | G21: 2.88 | H21: 12042.71

Sheet T2_Pop_Count_Sampling
A1: Pond ID | B1: Total Stocked (pcs) | C1: Day of Culture | D1: ABW (g) | E1: Est. Pop Count (pcs) | F1: Survival Rate (%) | G1: Est. Biomass (kg)
A2: A1 | B2: 4218543 | C2: 7 | D2: 4.33 | E2: 3120637 | F2: =T3_Pop_Count_Sampling[[#This Row],[Est. Pop Count (pcs)]]/T3_Pop_Count_Sampling[[#This Row],[Total Stocked (pcs)]]*100 -> 73.974284 | G2: =T3_Pop_Count_Sampling[[#This Row],[Est. Pop Count (pcs)]]*T3_Pop_Count_Sampling[[#This Row],[ABW (g)]]/1000 -> 13512.358
A3: A2 | B3: 4477821 | C3: 7 | D3: 3.72 | E3: 3334632 | F3: =T3_Pop_Count_Sampling[[#This Row],[Est. Pop Count (pcs)]]/T3_Pop_Count_Sampling[[#This Row],[Total Stocked (pcs)]]*100 -> 74.469971 | G3: =T3_Pop_Count_Sampling[[#This Row],[Est. Pop Count (pcs)]]*T3_Pop_Count_Sampling[[#This Row],[ABW (g)]]/1000 -> 12404.831
A4: A3 | B4: 4379397 | C4: 7 | D4: 3.62 | E4: 3244520 | F4: =T3_Pop_Count_Sampling[[#This Row],[Est. Pop Count (pcs)]]/T3_Pop_Count_Sampling[[#This Row],[Total Stocked (pcs)]]*100 -> 74.085999 | G4: =T3_Pop_Count_Sampling[[#This Row],[Est. Pop Count (pcs)]]*T3_Pop_Count_Sampling[[#This Row],[ABW (g)]]/1000 -> 11745.162
A5: A4 | B5: 4319396 | C5: 7 | D5: 4.55 | E5: 2352841 | F5: =T3_Pop_Count_Sampling[[#This Row],[Est. Pop Count (pcs)]]/T3_Pop_Count_Sampling[[#This Row],[Total Stocked (pcs)]]*100 -> 54.471528 | G5: =T3_Pop_Count_Sampling[[#This Row],[Est. Pop Count (pcs)]]*T3_Pop_Count_Sampling[[#This Row],[ABW (g)]]/1000 -> 10705.427
A6: A5 | B6: 4120208 | C6: 7 | D6: 4.15 | E6: 3072116 | F6: =T3_Pop_Count_Sampling[[#This Row],[Est. Pop Count (pcs)]]/T3_Pop_Count_Sampling[[#This Row],[Total Stocked (pcs)]]*100 -> 74.562158 | G6: =T3_Pop_Count_Sampling[[#This Row],[Est. Pop Count (pcs)]]*T3_Pop_Count_Sampling[[#This Row],[ABW (g)]]/1000 -> 12749.281
A7: B1 | B7: 4120198 | C7: 7 | D7: 5.17 | E7: 2064710 | F7: =T3_Pop_Count_Sampling[[#This Row],[Est. Pop Count (pcs)]]/T3_Pop_Count_Sampling[[#This Row],[Total Stocked (pcs)]]*100 -> 50.111912 | G7: =T3_Pop_Count_Sampling[[#This Row],[Est. Pop Count (pcs)]]*T3_Pop_Count_Sampling[[#This Row],[ABW (g)]]/1000 -> 10674.551
A8: B2 | B8: 4076138 | C8: 7 | D8: 3.68 | E8: 1951969 | F8: =T3_Pop_Count_Sampling[[#This Row],[Est. Pop Count (pcs)]]/T3_Pop_Count_Sampling[[#This Row],[Total Stocked (pcs)]]*100 -> 47.887706 | G8: =T3_Pop_Count_Sampling[[#This Row],[Est. Pop Count (pcs)]]*T3_Pop_Count_Sampling[[#This Row],[ABW (g)]]/1000 -> 7183.2459
A9: B3 | B9: 4439779 | C9: 7 | D9: 4.5 | E9: 2351740 | F9: =T3_Pop_Count_Sampling[[#This Row],[Est. Pop Count (pcs)]]/T3_Pop_Count_Sampling[[#This Row],[Total Stocked (pcs)]]*100 -> 52.969754 | G9: =T3_Pop_Count_Sampling[[#This Row],[Est. Pop Count (pcs)]]*T3_Pop_Count_Sampling[[#This Row],[ABW (g)]]/1000 -> 10582.83
A10: B4 | B10: 4320502 | C10: 7 | D10: 4.68 | E10: 3198674 | F10: =T3_Pop_Count_Sampling[[#This Row],[Est. Pop Count (pcs)]]/T3_Pop_Count_Sampling[[#This Row],[Total Stocked (pcs)]]*100 -> 74.034777 | G10: =T3_Pop_Count_Sampling[[#This Row],[Est. Pop Count (pcs)]]*T3_Pop_Count_Sampling[[#This Row],[ABW (g)]]/1000 -> 14969.794
A11: B5 | B11: 4368633 | C11: 7 | D11: 3.26 | E11: 3236070 | F11: =T3_Pop_Count_Sampling[[#This Row],[Est. Pop Count (pcs)]]/T3_Pop_Count_Sampling[[#This Row],[Total Stocked (pcs)]]*100 -> 74.075117 | G11: =T3_Pop_Count_Sampling[[#This Row],[Est. Pop Count (pcs)]]*T3_Pop_Count_Sampling[[#This Row],[ABW (g)]]/1000 -> 10549.588
A12: C1 | B12: 4059263 | C12: 7 | D12: 5.09 | E12: 2148969 | F12: =T3_Pop_Count_Sampling[[#This Row],[Est. Pop Count (pcs)]]/T3_Pop_Count_Sampling[[#This Row],[Total Stocked (pcs)]]*100 -> 52.939881 | G12: =T3_Pop_Count_Sampling[[#This Row],[Est. Pop Count (pcs)]]*T3_Pop_Count_Sampling[[#This Row],[ABW (g)]]/1000 -> 10938.252
A13: C2 | B13: 4486459 | C13: 7 | D13: 4.04 | E13: 3358270 | F13: =T3_Pop_Count_Sampling[[#This Row],[Est. Pop Count (pcs)]]/T3_Pop_Count_Sampling[[#This Row],[Total Stocked (pcs)]]*100 -> 74.853465 | G13: =T3_Pop_Count_Sampling[[#This Row],[Est. Pop Count (pcs)]]*T3_Pop_Count_Sampling[[#This Row],[ABW (g)]]/1000 -> 13567.411
... A181: D5 | B181: 4181053 | C181: 60 | D181: 14.32 | E181: 3040339 | F181: =T3_Pop_Count_Sampling[[#This Row],[Est. Pop Count (pcs)]]/T3_Pop_Count_Sampling[[#This Row],[Total Stocked (pcs)]]*100 -> 72.717064 | G181: =T3_Pop_Count_Sampling[[#This Row],[Est. Pop Count (pcs)]]*T3_Pop_Count_Sampling[[#This Row],[ABW (g)]]/1000 -> 43537.654

Sheet T3_Daily_Feed_Req
A1: Date | B1: Pond ID | C1: Area (ha) | D1: Stocked (pcs) | E1: Weekly ABW (g) | F1: DOC | G1: Latest Pop Count | H1: Current Biomass (kg) | I1: Calc Feed Rate (%) | J1: Daily Feed Req (kg)
A2: 46023 | B2: A1 | C2: 9.37 | D2: 4218543 | E2: 3.22 | F2: 1 | G2: 4218543 | H2: =T2_Daily_Feed_Req[[#This Row],[Weekly ABW (g)]]*T2_Daily_Feed_Req[[#This Row],[Latest Pop Count]]/1000 -> 13583.708 | I2: =VLOOKUP(T2_Daily_Feed_Req[[#This Row],[Weekly ABW (g)]],MAIN!$A$2:$B$10,2,TRUE) -> 7 | J2: =T2_Daily_Feed_Req[[#This Row],[Current Biomass (kg)]]*T2_Daily_Feed_Req[[#This Row],[Calc Feed Rate (%)]]/100 -> 950.85959
A3: 46023 | B3: A2 | C3: 9.95 | D3: 4477821 | E3: 2.28 | F3: 1 | G3: 4477821 | H3: =T2_Daily_Feed_Req[[#This Row],[Weekly ABW (g)]]*T2_Daily_Feed_Req[[#This Row],[Latest Pop Count]]/1000 -> 10209.432 | I3: =VLOOKUP(T2_Daily_Feed_Req[[#This Row],[Weekly ABW (g)]],MAIN!$A$2:$B$10,2,TRUE) -> 8 | J3: =T2_Daily_Feed_Req[[#This Row],[Current Biomass (kg)]]*T2_Daily_Feed_Req[[#This Row],[Calc Feed Rate (%)]]/100 -> 816.75455
A4: 46023 | B4: A3 | C4: 9.73 | D4: 4379397 | E4: 2.58 | F4: 1 | G4: 4379397 | H4: =T2_Daily_Feed_Req[[#This Row],[Weekly ABW (g)]]*T2_Daily_Feed_Req[[#This Row],[Latest Pop Count]]/1000 -> 11298.844 | I4: =VLOOKUP(T2_Daily_Feed_Req[[#This Row],[Weekly ABW (g)]],MAIN!$A$2:$B$10,2,TRUE) -> 8 | J4: =T2_Daily_Feed_Req[[#This Row],[Current Biomass (kg)]]*T2_Daily_Feed_Req[[#This Row],[Calc Feed Rate (%)]]/100 -> 903.90754
A5: 46023 | B5: A4 | C5: 9.6 | D5: 4319396 | E5: 2.73 | F5: 1 | G5: 4319396 | H5: =T2_Daily_Feed_Req[[#This Row],[Weekly ABW (g)]]*T2_Daily_Feed_Req[[#This Row],[Latest Pop Count]]/1000 -> 11791.951 | I5: =VLOOKUP(T2_Daily_Feed_Req[[#This Row],[Weekly ABW (g)]],MAIN!$A$2:$B$10,2,TRUE) -> 8 | J5: =T2_Daily_Feed_Req[[#This Row],[Current Biomass (kg)]]*T2_Daily_Feed_Req[[#This Row],[Calc Feed Rate (%)]]/100 -> 943.35609
A6: 46023 | B6: A5 | C6: 9.16 | D6: 4120208 | E6: 2.91 | F6: 1 | G6: 4120208 | H6: =T2_Daily_Feed_Req[[#This Row],[Weekly ABW (g)]]*T2_Daily_Feed_Req[[#This Row],[Latest Pop Count]]/1000 -> 11989.805 | I6: =VLOOKUP(T2_Daily_Feed_Req[[#This Row],[Weekly ABW (g)]],MAIN!$A$2:$B$10,2,TRUE) -> 8 | J6: =T2_Daily_Feed_Req[[#This Row],[Current Biomass (kg)]]*T2_Daily_Feed_Req[[#This Row],[Calc Feed Rate (%)]]/100 -> 959.18442
A7: 46024 | B7: B1 | C7: 9.16 | D7: 4120198 | E7: 3.57 | F7: 1 | G7: 4120198 | H7: =T2_Daily_Feed_Req[[#This Row],[Weekly ABW (g)]]*T2_Daily_Feed_Req[[#This Row],[Latest Pop Count]]/1000 -> 14709.107 | I7: =VLOOKUP(T2_Daily_Feed_Req[[#This Row],[Weekly ABW (g)]],MAIN!$A$2:$B$10,2,TRUE) -> 7 | J7: =T2_Daily_Feed_Req[[#This Row],[Current Biomass (kg)]]*T2_Daily_Feed_Req[[#This Row],[Calc Feed Rate (%)]]/100 -> 1029.6375
A8: 46024 | B8: B2 | C8: 9.06 | D8: 4076138 | E8: 2.4 | F8: 1 | G8: 4076138 | H8: =T2_Daily_Feed_Req[[#This Row],[Weekly ABW (g)]]*T2_Daily_Feed_Req[[#This Row],[Latest Pop Count]]/1000 -> 9782.7312 | I8: =VLOOKUP(T2_Daily_Feed_Req[[#This Row],[Weekly ABW (g)]],MAIN!$A$2:$B$10,2,TRUE) -> 8 | J8: =T2_Daily_Feed_Req[[#This Row],[Current Biomass (kg)]]*T2_Daily_Feed_Req[[#This Row],[Calc Feed Rate (%)]]/100 -> 782.6185
A9: 46024 | B9: B3 | C9: 9.87 | D9: 4439779 | E9: 3.03 | F9: 1 | G9: 4439779 | H9: =T2_Daily_Feed_Req[[#This Row],[Weekly ABW (g)]]*T2_Daily_Feed_Req[[#This Row],[Latest Pop Count]]/1000 -> 13452.53 | I9: =VLOOKUP(T2_Daily_Feed_Req[[#This Row],[Weekly ABW (g)]],MAIN!$A$2:$B$10,2,TRUE) -> 7 | J9: =T2_Daily_Feed_Req[[#This Row],[Current Biomass (kg)]]*T2_Daily_Feed_Req[[#This Row],[Calc Feed Rate (%)]]/100 -> 941.67713
A10: 46024 | B10: B4 | C10: 9.6 | D10: 4320502 | E10: 3.18 | F10: 1 | G10: 4320502 | H10: =T2_Daily_Feed_Req[[#This Row],[Weekly ABW (g)]]*T2_Daily_Feed_Req[[#This Row],[Latest Pop Count]]/1000 -> 13739.196 | I10: =VLOOKUP(T2_Daily_Feed_Req[[#This Row],[Weekly ABW (g)]],MAIN!$A$2:$B$10,2,TRUE) -> 7 | J10: =T2_Daily_Feed_Req[[#This Row],[Current Biomass (kg)]]*T2_Daily_Feed_Req[[#This Row],[Calc Feed Rate (%)]]/100 -> 961.74375
A11: 46024 | B11: B5 | C11: 9.71 | D11: 4368633 | E11: 2.09 | F11: 1 | G11: 4368633 | H11: =T2_Daily_Feed_Req[[#This Row],[Weekly ABW (g)]]*T2_Daily_Feed_Req[[#This Row],[Latest Pop Count]]/1000 -> 9130.443 | I11: =VLOOKUP(T2_Daily_Feed_Req[[#This Row],[Weekly ABW (g)]],MAIN!$A$2:$B$10,2,TRUE) -> 8 | J11: =T2_Daily_Feed_Req[[#This Row],[Current Biomass (kg)]]*T2_Daily_Feed_Req[[#This Row],[Calc Feed Rate (%)]]/100 -> 730.43544
A12: 46025 | B12: C1 | C12: 9.02 | D12: 4059263 | E12: 3.22 | F12: 1 | G12: 4059263 | H12: =T2_Daily_Feed_Req[[#This Row],[Weekly ABW (g)]]*T2_Daily_Feed_Req[[#This Row],[Latest Pop Count]]/1000 -> 13070.827 | I12: =VLOOKUP(T2_Daily_Feed_Req[[#This Row],[Weekly ABW (g)]],MAIN!$A$2:$B$10,2,TRUE) -> 7 | J12: =T2_Daily_Feed_Req[[#This Row],[Current Biomass (kg)]]*T2_Daily_Feed_Req[[#This Row],[Calc Feed Rate (%)]]/100 -> 914.95788
A13: 46025 | B13: C2 | C13: 9.97 | D13: 4486459 | E13: 2.34 | F13: 1 | G13: 4486459 | H13: =T2_Daily_Feed_Req[[#This Row],[Weekly ABW (g)]]*T2_Daily_Feed_Req[[#This Row],[Latest Pop Count]]/1000 -> 10498.314 | I13: =VLOOKUP(T2_Daily_Feed_Req[[#This Row],[Weekly ABW (g)]],MAIN!$A$2:$B$10,2,TRUE) -> 8 | J13: =T2_Daily_Feed_Req[[#This Row],[Current Biomass (kg)]]*T2_Daily_Feed_Req[[#This Row],[Calc Feed Rate (%)]]/100 -> 839.86512
... A21: 46026 | B21: D5 | C21: 9.29 | D21: 4181053 | E21: 2.88 | F21: 1 | G21: 4181053 | H21: =T2_Daily_Feed_Req[[#This Row],[Weekly ABW (g)]]*T2_Daily_Feed_Req[[#This Row],[Latest Pop Count]]/1000 -> 12041.433 | I21: =VLOOKUP(T2_Daily_Feed_Req[[#This Row],[Weekly ABW (g)]],MAIN!$A$2:$B$10,2,TRUE) -> 8 | J21: =T2_Daily_Feed_Req[[#This Row],[Current Biomass (kg)]]*T2_Daily_Feed_Req[[#This Row],[Calc Feed Rate (%)]]/100 -> 963.31461
A22: =A2+6 -> 46029 | B22: A1 | C22: 9.37 | D22: 4218543 | E22: 4.33 | F22: 7 | G22: 3120637 | H22: =T2_Daily_Feed_Req[[#This Row],[Weekly ABW (g)]]*T2_Daily_Feed_Req[[#This Row],[Latest Pop Count]]/1000 -> 13512.358 | I22: =VLOOKUP(T2_Daily_Feed_Req[[#This Row],[Weekly ABW (g)]],MAIN!$A$2:$B$10,2,TRUE) -> 7 | J22: =T2_Daily_Feed_Req[[#This Row],[Current Biomass (kg)]]*T2_Daily_Feed_Req[[#This Row],[Calc Feed Rate (%)]]/100 -> 945.86507
A23: =A3+6 -> 46029 | B23: A2 | C23: 9.95 | D23: 4477821 | E23: 3.72 | F23: 7 | G23: 3334632 | H23: =T2_Daily_Feed_Req[[#This Row],[Weekly ABW (g)]]*T2_Daily_Feed_Req[[#This Row],[Latest Pop Count]]/1000 -> 12404.831 | I23: =VLOOKUP(T2_Daily_Feed_Req[[#This Row],[Weekly ABW (g)]],MAIN!$A$2:$B$10,2,TRUE) -> 7 | J23: =T2_Daily_Feed_Req[[#This Row],[Current Biomass (kg)]]*T2_Daily_Feed_Req[[#This Row],[Calc Feed Rate (%)]]/100 -> 868.33817
A24: =A4+6 -> 46029 | B24: A3 | C24: 9.73 | D24: 4379397 | E24: 3.62 | F24: 7 | G24: 3244520 | H24: =T2_Daily_Feed_Req[[#This Row],[Weekly ABW (g)]]*T2_Daily_Feed_Req[[#This Row],[Latest Pop Count]]/1000 -> 11745.162 | I24: =VLOOKUP(T2_Daily_Feed_Req[[#This Row],[Weekly ABW (g)]],MAIN!$A$2:$B$10,2,TRUE) -> 7 | J24: =T2_Daily_Feed_Req[[#This Row],[Current Biomass (kg)]]*T2_Daily_Feed_Req[[#This Row],[Calc Feed Rate (%)]]/100 -> 822.16137
A25: =A5+6 -> 46029 | B25: A4 | C25: 9.6 | D25: 4319396 | E25: 4.55 | F25: 7 | G25: 2352841 | H25: =T2_Daily_Feed_Req[[#This Row],[Weekly ABW (g)]]*T2_Daily_Feed_Req[[#This Row],[Latest Pop Count]]/1000 -> 10705.427 | I25: =VLOOKUP(T2_Daily_Feed_Req[[#This Row],[Weekly ABW (g)]],MAIN!$A$2:$B$10,2,TRUE) -> 7 | J25: =T2_Daily_Feed_Req[[#This Row],[Current Biomass (kg)]]*T2_Daily_Feed_Req[[#This Row],[Calc Feed Rate (%)]]/100 -> 749.37986
A26: =A6+6 -> 46029 | B26: A5 | C26: 9.16 | D26: 4120208 | E26: 4.15 | F26: 7 | G26: 3072116 | H26: =T2_Daily_Feed_Req[[#This Row],[Weekly ABW (g)]]*T2_Daily_Feed_Req[[#This Row],[Latest Pop Count]]/1000 -> 12749.281 | I26: =VLOOKUP(T2_Daily_Feed_Req[[#This Row],[Weekly ABW (g)]],MAIN!$A$2:$B$10,2,TRUE) -> 7 | J26: =T2_Daily_Feed_Req[[#This Row],[Current Biomass (kg)]]*T2_Daily_Feed_Req[[#This Row],[Calc Feed Rate (%)]]/100 -> 892.4497
A27: =A7+6 -> 46030 | B27: B1 | C27: 9.16 | D27: 4120198 | E27: 5.17 | F27: 7 | G27: 2064710 | H27: =T2_Daily_Feed_Req[[#This Row],[Weekly ABW (g)]]*T2_Daily_Feed_Req[[#This Row],[Latest Pop Count]]/1000 -> 10674.551 | I27: =VLOOKUP(T2_Daily_Feed_Req[[#This Row],[Weekly ABW (g)]],MAIN!$A$2:$B$10,2,TRUE) -> 5.5 | J27: =T2_Daily_Feed_Req[[#This Row],[Current Biomass (kg)]]*T2_Daily_Feed_Req[[#This Row],[Calc Feed Rate (%)]]/100 -> 587.10029
A28: =A8+6 -> 46030 | B28: B2 | C28: 9.06 | D28: 4076138 | E28: 3.68 | F28: 7 | G28: 1951969 | H28: =T2_Daily_Feed_Req[[#This Row],[Weekly ABW (g)]]*T2_Daily_Feed_Req[[#This Row],[Latest Pop Count]]/1000 -> 7183.2459 | I28: =VLOOKUP(T2_Daily_Feed_Req[[#This Row],[Weekly ABW (g)]],MAIN!$A$2:$B$10,2,TRUE) -> 7 | J28: =T2_Daily_Feed_Req[[#This Row],[Current Biomass (kg)]]*T2_Daily_Feed_Req[[#This Row],[Calc Feed Rate (%)]]/100 -> 502.82721
A29: =A9+6 -> 46030 | B29: B3 | C29: 9.87 | D29: 4439779 | E29: 4.5 | F29: 7 | G29: 2351740 | H29: =T2_Daily_Feed_Req[[#This Row],[Weekly ABW (g)]]*T2_Daily_Feed_Req[[#This Row],[Latest Pop Count]]/1000 -> 10582.83 | I29: =VLOOKUP(T2_Daily_Feed_Req[[#This Row],[Weekly ABW (g)]],MAIN!$A$2:$B$10,2,TRUE) -> 7 | J29: =T2_Daily_Feed_Req[[#This Row],[Current Biomass (kg)]]*T2_Daily_Feed_Req[[#This Row],[Calc Feed Rate (%)]]/100 -> 740.7981
A30: =A10+6 -> 46030 | B30: B4 | C30: 9.6 | D30: 4320502 | E30: 4.68 | F30: 7 | G30: 3198674 | H30: =T2_Daily_Feed_Req[[#This Row],[Weekly ABW (g)]]*T2_Daily_Feed_Req[[#This Row],[Latest Pop Count]]/1000 -> 14969.794 | I30: =VLOOKUP(T2_Daily_Feed_Req[[#This Row],[Weekly ABW (g)]],MAIN!$A$2:$B$10,2,TRUE) -> 7 | J30: =T2_Daily_Feed_Req[[#This Row],[Current Biomass (kg)]]*T2_Daily_Feed_Req[[#This Row],[Calc Feed Rate (%)]]/100 -> 1047.8856
A31: =A11+6 -> 46030 | B31: B5 | C31: 9.71 | D31: 4368633 | E31: 3.26 | F31: 7 | G31: 3236070 | H31: =T2_Daily_Feed_Req[[#This Row],[Weekly ABW (g)]]*T2_Daily_Feed_Req[[#This Row],[Latest Pop Count]]/1000 -> 10549.588 | I31: =VLOOKUP(T2_Daily_Feed_Req[[#This Row],[Weekly ABW (g)]],MAIN!$A$2:$B$10,2,TRUE) -> 7 | J31: =T2_Daily_Feed_Req[[#This Row],[Current Biomass (kg)]]*T2_Daily_Feed_Req[[#This Row],[Calc Feed Rate (%)]]/100 -> 738.47117
A32: =A12+6 -> 46031 | B32: C1 | C32: 9.02 | D32: 4059263 | E32: 5.09 | F32: 7 | G32: 2148969 | H32: =T2_Daily_Feed_Req[[#This Row],[Weekly ABW (g)]]*T2_Daily_Feed_Req[[#This Row],[Latest Pop Count]]/1000 -> 10938.252 | I32: =VLOOKUP(T2_Daily_Feed_Req[[#This Row],[Weekly ABW (g)]],MAIN!$A$2:$B$10,2,TRUE) -> 5.5 | J32: =T2_Daily_Feed_Req[[#This Row],[Current Biomass (kg)]]*T2_Daily_Feed_Req[[#This Row],[Calc Feed Rate (%)]]/100 -> 601.60387
A33: =A13+6 -> 46031 | B33: C2 | C33: 9.97 | D33: 4486459 | E33: 4.04 | F33: 7 | G33: 3358270 | H33: =T2_Daily_Feed_Req[[#This Row],[Weekly ABW (g)]]*T2_Daily_Feed_Req[[#This Row],[Latest Pop Count]]/1000 -> 13567.411 | I33: =VLOOKUP(T2_Daily_Feed_Req[[#This Row],[Weekly ABW (g)]],MAIN!$A$2:$B$10,2,TRUE) -> 7 | J33: =T2_Daily_Feed_Req[[#This Row],[Current Biomass (kg)]]*T2_Daily_Feed_Req[[#This Row],[Calc Feed Rate (%)]]/100 -> 949.71876
... A41: =A21+6 -> 46032 | B41: D5 | C41: 9.29 | D41: 4181053 | E41: 4.17 | F41: 7 | G41: 3105252 | H41: =T2_Daily_Feed_Req[[#This Row],[Weekly ABW (g)]]*T2_Daily_Feed_Req[[#This Row],[Latest Pop Count]]/1000 -> 12948.901 | I41: =VLOOKUP(T2_Daily_Feed_Req[[#This Row],[Weekly ABW (g)]],MAIN!$A$2:$B$10,2,TRUE) -> 7 | J41: =T2_Daily_Feed_Req[[#This Row],[Current Biomass (kg)]]*T2_Daily_Feed_Req[[#This Row],[Calc Feed Rate (%)]]/100 -> 906.42306
A42: =A22+7 -> 46036 | B42: A1 | C42: 9.37 | D42: 4218543 | E42: 5.36 | F42: 14 | G42: 3115603 | H42: =T2_Daily_Feed_Req[[#This Row],[Weekly ABW (g)]]*T2_Daily_Feed_Req[[#This Row],[Latest Pop Count]]/1000 -> 16699.632 | I42: =VLOOKUP(T2_Daily_Feed_Req[[#This Row],[Weekly ABW (g)]],MAIN!$A$2:$B$10,2,TRUE) -> 5.5 | J42: =T2_Daily_Feed_Req[[#This Row],[Current Biomass (kg)]]*T2_Daily_Feed_Req[[#This Row],[Calc Feed Rate (%)]]/100 -> 918.47976
A43: =A23+7 -> 46036 | B43: A2 | C43: 9.95 | D43: 4477821 | E43: 5.3 | F43: 14 | G43: 3319447 | H43: =T2_Daily_Feed_Req[[#This Row],[Weekly ABW (g)]]*T2_Daily_Feed_Req[[#This Row],[Latest Pop Count]]/1000 -> 17593.069 | I43: =VLOOKUP(T2_Daily_Feed_Req[[#This Row],[Weekly ABW (g)]],MAIN!$A$2:$B$10,2,TRUE) -> 5.5 | J43: =T2_Daily_Feed_Req[[#This Row],[Current Biomass (kg)]]*T2_Daily_Feed_Req[[#This Row],[Calc Feed Rate (%)]]/100 -> 967.6188
A44: =A24+7 -> 46036 | B44: A3 | C44: 9.73 | D44: 4379397 | E44: 4.9 | F44: 14 | G44: 3237188 | H44: =T2_Daily_Feed_Req[[#This Row],[Weekly ABW (g)]]*T2_Daily_Feed_Req[[#This Row],[Latest Pop Count]]/1000 -> 15862.221 | I44: =VLOOKUP(T2_Daily_Feed_Req[[#This Row],[Weekly ABW (g)]],MAIN!$A$2:$B$10,2,TRUE) -> 7 | J44: =T2_Daily_Feed_Req[[#This Row],[Current Biomass (kg)]]*T2_Daily_Feed_Req[[#This Row],[Calc Feed Rate (%)]]/100 -> 1110.3555
A45: =A25+7 -> 46036 | B45: A4 | C45: 9.6 | D45: 4319396 | E45: 6.01 | F45: 14 | G45: 2329789 | H45: =T2_Daily_Feed_Req[[#This Row],[Weekly ABW (g)]]*T2_Daily_Feed_Req[[#This Row],[Latest Pop Count]]/1000 -> 14002.032 | I45: =VLOOKUP(T2_Daily_Feed_Req[[#This Row],[Weekly ABW (g)]],MAIN!$A$2:$B$10,2,TRUE) -> 5.5 | J45: =T2_Daily_Feed_Req[[#This Row],[Current Biomass (kg)]]*T2_Daily_Feed_Req[[#This Row],[Calc Feed Rate (%)]]/100 -> 770.11175
A46: =A26+7 -> 46036 | B46: A5 | C46: 9.16 | D46: 4120208 | E46: 5.96 | F46: 14 | G46: 3061469 | H46: =T2_Daily_Feed_Req[[#This Row],[Weekly ABW (g)]]*T2_Daily_Feed_Req[[#This Row],[Latest Pop Count]]/1000 -> 18246.355 | I46: =VLOOKUP(T2_Daily_Feed_Req[[#This Row],[Weekly ABW (g)]],MAIN!$A$2:$B$10,2,TRUE) -> 5.5 | J46: =T2_Daily_Feed_Req[[#This Row],[Current Biomass (kg)]]*T2_Daily_Feed_Req[[#This Row],[Calc Feed Rate (%)]]/100 -> 1003.5495
A47: =A27+7 -> 46037 | B47: B1 | C47: 9.16 | D47: 4120198 | E47: 6.39 | F47: 14 | G47: 2028932 | H47: =T2_Daily_Feed_Req[[#This Row],[Weekly ABW (g)]]*T2_Daily_Feed_Req[[#This Row],[Latest Pop Count]]/1000 -> 12964.875 | I47: =VLOOKUP(T2_Daily_Feed_Req[[#This Row],[Weekly ABW (g)]],MAIN!$A$2:$B$10,2,TRUE) -> 5.5 | J47: =T2_Daily_Feed_Req[[#This Row],[Current Biomass (kg)]]*T2_Daily_Feed_Req[[#This Row],[Calc Feed Rate (%)]]/100 -> 713.06815
A48: =A28+7 -> 46037 | B48: B2 | C48: 9.06 | D48: 4076138 | E48: 5.05 | F48: 14 | G48: 1914623 | H48: =T2_Daily_Feed_Req[[#This Row],[Weekly ABW (g)]]*T2_Daily_Feed_Req[[#This Row],[Latest Pop Count]]/1000 -> 9668.8462 | I48: =VLOOKUP(T2_Daily_Feed_Req[[#This Row],[Weekly ABW (g)]],MAIN!$A$2:$B$10,2,TRUE) -> 5.5 | J48: =T2_Daily_Feed_Req[[#This Row],[Current Biomass (kg)]]*T2_Daily_Feed_Req[[#This Row],[Calc Feed Rate (%)]]/100 -> 531.78654
A49: =A29+7 -> 46037 | B49: B3 | C49: 9.87 | D49: 4439779 | E49: 6.18 | F49: 14 | G49: 2315824 | H49: =T2_Daily_Feed_Req[[#This Row],[Weekly ABW (g)]]*T2_Daily_Feed_Req[[#This Row],[Latest Pop Count]]/1000 -> 14311.792 | I49: =VLOOKUP(T2_Daily_Feed_Req[[#This Row],[Weekly ABW (g)]],MAIN!$A$2:$B$10,2,TRUE) -> 5.5 | J49: =T2_Daily_Feed_Req[[#This Row],[Current Biomass (kg)]]*T2_Daily_Feed_Req[[#This Row],[Calc Feed Rate (%)]]/100 -> 787.14858
A50: =A30+7 -> 46037 | B50: B4 | C50: 9.6 | D50: 4320502 | E50: 5.88 | F50: 14 | G50: 3182044 | H50: =T2_Daily_Feed_Req[[#This Row],[Weekly ABW (g)]]*T2_Daily_Feed_Req[[#This Row],[Latest Pop Count]]/1000 -> 18710.419 | I50: =VLOOKUP(T2_Daily_Feed_Req[[#This Row],[Weekly ABW (g)]],MAIN!$A$2:$B$10,2,TRUE) -> 5.5 | J50: =T2_Daily_Feed_Req[[#This Row],[Current Biomass (kg)]]*T2_Daily_Feed_Req[[#This Row],[Calc Feed Rate (%)]]/100 -> 1029.073
A51: =A31+7 -> 46037 | B51: B5 | C51: 9.71 | D51: 4368633 | E51: 4.33 | F51: 14 | G51: 3232163 | H51: =T2_Daily_Feed_Req[[#This Row],[Weekly ABW (g)]]*T2_Daily_Feed_Req[[#This Row],[Latest Pop Count]]/1000 -> 13995.266 | I51: =VLOOKUP(T2_Daily_Feed_Req[[#This Row],[Weekly ABW (g)]],MAIN!$A$2:$B$10,2,TRUE) -> 7 | J51: =T2_Daily_Feed_Req[[#This Row],[Current Biomass (kg)]]*T2_Daily_Feed_Req[[#This Row],[Calc Feed Rate (%)]]/100 -> 979.66861
A52: =A32+7 -> 46038 | B52: C1 | C52: 9.02 | D52: 4059263 | E52: 6.35 | F52: 14 | G52: 2133384 | H52: =T2_Daily_Feed_Req[[#This Row],[Weekly ABW (g)]]*T2_Daily_Feed_Req[[#This Row],[Latest Pop Count]]/1000 -> 13546.988 | I52: =VLOOKUP(T2_Daily_Feed_Req[[#This Row],[Weekly ABW (g)]],MAIN!$A$2:$B$10,2,TRUE) -> 5.5 | J52: =T2_Daily_Feed_Req[[#This Row],[Current Biomass (kg)]]*T2_Daily_Feed_Req[[#This Row],[Calc Feed Rate (%)]]/100 -> 745.08436
A53: =A33+7 -> 46038 | B53: C2 | C53: 9.97 | D53: 4486459 | E53: 5.18 | F53: 14 | G53: 3344511 | H53: =T2_Daily_Feed_Req[[#This Row],[Weekly ABW (g)]]*T2_Daily_Feed_Req[[#This Row],[Latest Pop Count]]/1000 -> 17324.567 | I53: =VLOOKUP(T2_Daily_Feed_Req[[#This Row],[Weekly ABW (g)]],MAIN!$A$2:$B$10,2,TRUE) -> 5.5 | J53: =T2_Daily_Feed_Req[[#This Row],[Current Biomass (kg)]]*T2_Daily_Feed_Req[[#This Row],[Calc Feed Rate (%)]]/100 -> 952.85118
... A201: =A181+7 -> 46088 | B201: D5 | C201: 9.29 | D201: 4181053 | E201: 14.32 | F201: 60 | G201: 3040339 | H201: =T2_Daily_Feed_Req[[#This Row],[Weekly ABW (g)]]*T2_Daily_Feed_Req[[#This Row],[Latest Pop Count]]/1000 -> 43537.654 | I201: =VLOOKUP(T2_Daily_Feed_Req[[#This Row],[Weekly ABW (g)]],MAIN!$A$2:$B$10,2,TRUE) -> 4.5 | J201: =T2_Daily_Feed_Req[[#This Row],[Current Biomass (kg)]]*T2_Daily_Feed_Req[[#This Row],[Calc Feed Rate (%)]]/100 -> 1959.1945

Sheet T5_Weekly_Feed_Calc
A1: Pond ID | B1: Day of Culture | C1: Sampling ABW (g) | D1: Pop Count | E1: Biomass (kg) | F1: Feed Rate (%) | G1: Daily Feed Req (kg)
A2: A1 | B2: 7 | C2: 4.33 | D2: 3120637 | E2: =T5_Weekly_Feed_Calc[[#This Row],[Pop Count]]*T5_Weekly_Feed_Calc[[#This Row],[Sampling ABW (g)]]/1000 -> 13512.358 | F2: =VLOOKUP(T5_Weekly_Feed_Calc[[#This Row],[Sampling ABW (g)]],MAIN!$A$2:$B$10,2,TRUE) -> 7 | G2: =T5_Weekly_Feed_Calc[[#This Row],[Biomass (kg)]]*T5_Weekly_Feed_Calc[[#This Row],[Feed Rate (%)]]/100 -> 945.86507
A3: A2 | B3: 7 | C3: 3.72 | D3: 3334632 | E3: 16351.86 | F3: =VLOOKUP(T5_Weekly_Feed_Calc[[#This Row],[Sampling ABW (g)]],MAIN!$A$2:$B$10,2,TRUE) -> 7 | G3: =T5_Weekly_Feed_Calc[[#This Row],[Biomass (kg)]]*T5_Weekly_Feed_Calc[[#This Row],[Feed Rate (%)]]/100 -> 1144.6302
A4: A3 | B4: 7 | C4: 3.62 | D4: 3244520 | E4: 15699.17 | F4: =VLOOKUP(T5_Weekly_Feed_Calc[[#This Row],[Sampling ABW (g)]],MAIN!$A$2:$B$10,2,TRUE) -> 7 | G4: =T5_Weekly_Feed_Calc[[#This Row],[Biomass (kg)]]*T5_Weekly_Feed_Calc[[#This Row],[Feed Rate (%)]]/100 -> 1098.9419
A5: A4 | B5: 7 | C5: 4.55 | D5: 2352841 | E5: 19306.87 | F5: =VLOOKUP(T5_Weekly_Feed_Calc[[#This Row],[Sampling ABW (g)]],MAIN!$A$2:$B$10,2,TRUE) -> 7 | G5: =T5_Weekly_Feed_Calc[[#This Row],[Biomass (kg)]]*T5_Weekly_Feed_Calc[[#This Row],[Feed Rate (%)]]/100 -> 1351.4809
A6: A5 | B6: 7 | C6: 4.15 | D6: 3072116 | E6: 16747.43 | F6: =VLOOKUP(T5_Weekly_Feed_Calc[[#This Row],[Sampling ABW (g)]],MAIN!$A$2:$B$10,2,TRUE) -> 7 | G6: =T5_Weekly_Feed_Calc[[#This Row],[Biomass (kg)]]*T5_Weekly_Feed_Calc[[#This Row],[Feed Rate (%)]]/100 -> 1172.3201
A7: B1 | B7: 7 | C7: 5.17 | D7: 2064710 | E7: 20986.37 | F7: =VLOOKUP(T5_Weekly_Feed_Calc[[#This Row],[Sampling ABW (g)]],MAIN!$A$2:$B$10,2,TRUE) -> 5.5 | G7: =T5_Weekly_Feed_Calc[[#This Row],[Biomass (kg)]]*T5_Weekly_Feed_Calc[[#This Row],[Feed Rate (%)]]/100 -> 1154.2503
A8: B2 | B8: 7 | C8: 3.68 | D8: 1951969 | E8: 14667.01 | F8: =VLOOKUP(T5_Weekly_Feed_Calc[[#This Row],[Sampling ABW (g)]],MAIN!$A$2:$B$10,2,TRUE) -> 7 | G8: =T5_Weekly_Feed_Calc[[#This Row],[Biomass (kg)]]*T5_Weekly_Feed_Calc[[#This Row],[Feed Rate (%)]]/100 -> 1026.6907
A9: B3 | B9: 7 | C9: 4.5 | D9: 2351740 | E9: 19784.81 | F9: =VLOOKUP(T5_Weekly_Feed_Calc[[#This Row],[Sampling ABW (g)]],MAIN!$A$2:$B$10,2,TRUE) -> 7 | G9: =T5_Weekly_Feed_Calc[[#This Row],[Biomass (kg)]]*T5_Weekly_Feed_Calc[[#This Row],[Feed Rate (%)]]/100 -> 1384.9367
A10: B4 | B10: 7 | C10: 4.68 | D10: 3198674 | E10: 19731.39 | F10: =VLOOKUP(T5_Weekly_Feed_Calc[[#This Row],[Sampling ABW (g)]],MAIN!$A$2:$B$10,2,TRUE) -> 7 | G10: =T5_Weekly_Feed_Calc[[#This Row],[Biomass (kg)]]*T5_Weekly_Feed_Calc[[#This Row],[Feed Rate (%)]]/100 -> 1381.1973
A11: B5 | B11: 7 | C11: 3.26 | D11: 3236070 | E11: 14163.63 | F11: =VLOOKUP(T5_Weekly_Feed_Calc[[#This Row],[Sampling ABW (g)]],MAIN!$A$2:$B$10,2,TRUE) -> 7 | G11: =T5_Weekly_Feed_Calc[[#This Row],[Biomass (kg)]]*T5_Weekly_Feed_Calc[[#This Row],[Feed Rate (%)]]/100 -> 991.4541
A12: C1 | B12: 7 | C12: 5.09 | D12: 2148969 | E12: 20455.04 | F12: =VLOOKUP(T5_Weekly_Feed_Calc[[#This Row],[Sampling ABW (g)]],MAIN!$A$2:$B$10,2,TRUE) -> 5.5 | G12: =T5_Weekly_Feed_Calc[[#This Row],[Biomass (kg)]]*T5_Weekly_Feed_Calc[[#This Row],[Feed Rate (%)]]/100 -> 1125.0272
A13: C2 | B13: 7 | C13: 4.04 | D13: 3358270 | E13: 17738.35 | F13: =VLOOKUP(T5_Weekly_Feed_Calc[[#This Row],[Sampling ABW (g)]],MAIN!$A$2:$B$10,2,TRUE) -> 7 | G13: =T5_Weekly_Feed_Calc[[#This Row],[Biomass (kg)]]*T5_Weekly_Feed_Calc[[#This Row],[Feed Rate (%)]]/100 -> 1241.6845
A14: C3 | B14: 7 | C14: 3.98 | D14: 3301985 | E14: 17152.84 | F14: =VLOOKUP(T5_Weekly_Feed_Calc[[#This Row],[Sampling ABW (g)]],MAIN!$A$2:$B$10,2,TRUE) -> 7 | G14: =T5_Weekly_Feed_Calc[[#This Row],[Biomass (kg)]]*T5_Weekly_Feed_Calc[[#This Row],[Feed Rate (%)]]/100 -> 1200.6988
... A21: D5 | B21: 7 | C21: 4.17 | D21: 3105252 | E21: 17052.2 | F21: =VLOOKUP(T5_Weekly_Feed_Calc[[#This Row],[Sampling ABW (g)]],MAIN!$A$2:$B$10,2,TRUE) -> 7 | G21: =T5_Weekly_Feed_Calc[[#This Row],[Biomass (kg)]]*T5_Weekly_Feed_Calc[[#This Row],[Feed Rate (%)]]/100 -> 1193.654
A22: A1 | B22: 14 | C22: 5.36 | D22: 3115603 | E22: =T5_Weekly_Feed_Calc[[#This Row],[Pop Count]]*T5_Weekly_Feed_Calc[[#This Row],[Sampling ABW (g)]]/1000 -> 16699.632 | F22: =VLOOKUP(T5_Weekly_Feed_Calc[[#This Row],[Sampling ABW (g)]],MAIN!$A$2:$B$10,2,TRUE) -> 5.5 | G22: =T5_Weekly_Feed_Calc[[#This Row],[Biomass (kg)]]*T5_Weekly_Feed_Calc[[#This Row],[Feed Rate (%)]]/100 -> 918.47976
A23: A2 | B23: 14 | C23: 5.3 | D23: 3319447 | E23: 23091.98 | F23: =VLOOKUP(T5_Weekly_Feed_Calc[[#This Row],[Sampling ABW (g)]],MAIN!$A$2:$B$10,2,TRUE) -> 5.5 | G23: =T5_Weekly_Feed_Calc[[#This Row],[Biomass (kg)]]*T5_Weekly_Feed_Calc[[#This Row],[Feed Rate (%)]]/100 -> 1270.0589
A24: A3 | B24: 14 | C24: 4.9 | D24: 3237188 | E24: 20873.78 | F24: =VLOOKUP(T5_Weekly_Feed_Calc[[#This Row],[Sampling ABW (g)]],MAIN!$A$2:$B$10,2,TRUE) -> 7 | G24: =T5_Weekly_Feed_Calc[[#This Row],[Biomass (kg)]]*T5_Weekly_Feed_Calc[[#This Row],[Feed Rate (%)]]/100 -> 1461.1646
A25: A4 | B25: 14 | C25: 6.01 | D25: 2329789 | E25: 24909.66 | F25: =VLOOKUP(T5_Weekly_Feed_Calc[[#This Row],[Sampling ABW (g)]],MAIN!$A$2:$B$10,2,TRUE) -> 5.5 | G25: =T5_Weekly_Feed_Calc[[#This Row],[Biomass (kg)]]*T5_Weekly_Feed_Calc[[#This Row],[Feed Rate (%)]]/100 -> 1370.0313
A26: A5 | B26: 14 | C26: 5.96 | D26: 3061469 | E26: 23595.6 | F26: =VLOOKUP(T5_Weekly_Feed_Calc[[#This Row],[Sampling ABW (g)]],MAIN!$A$2:$B$10,2,TRUE) -> 5.5 | G26: =T5_Weekly_Feed_Calc[[#This Row],[Biomass (kg)]]*T5_Weekly_Feed_Calc[[#This Row],[Feed Rate (%)]]/100 -> 1297.758
A27: B1 | B27: 14 | C27: 6.39 | D27: 2028932 | E27: 25532.38 | F27: =VLOOKUP(T5_Weekly_Feed_Calc[[#This Row],[Sampling ABW (g)]],MAIN!$A$2:$B$10,2,TRUE) -> 5.5 | G27: =T5_Weekly_Feed_Calc[[#This Row],[Biomass (kg)]]*T5_Weekly_Feed_Calc[[#This Row],[Feed Rate (%)]]/100 -> 1404.2809
A28: B2 | B28: 14 | C28: 5.05 | D28: 1914623 | E28: 19950.97 | F28: =VLOOKUP(T5_Weekly_Feed_Calc[[#This Row],[Sampling ABW (g)]],MAIN!$A$2:$B$10,2,TRUE) -> 5.5 | G28: =T5_Weekly_Feed_Calc[[#This Row],[Biomass (kg)]]*T5_Weekly_Feed_Calc[[#This Row],[Feed Rate (%)]]/100 -> 1097.3034
A29: B3 | B29: 14 | C29: 6.18 | D29: 2315824 | E29: 26965.23 | F29: =VLOOKUP(T5_Weekly_Feed_Calc[[#This Row],[Sampling ABW (g)]],MAIN!$A$2:$B$10,2,TRUE) -> 5.5 | G29: =T5_Weekly_Feed_Calc[[#This Row],[Biomass (kg)]]*T5_Weekly_Feed_Calc[[#This Row],[Feed Rate (%)]]/100 -> 1483.0876
A30: B4 | B30: 14 | C30: 5.88 | D30: 3182044 | E30: 24202.05 | F30: =VLOOKUP(T5_Weekly_Feed_Calc[[#This Row],[Sampling ABW (g)]],MAIN!$A$2:$B$10,2,TRUE) -> 5.5 | G30: =T5_Weekly_Feed_Calc[[#This Row],[Biomass (kg)]]*T5_Weekly_Feed_Calc[[#This Row],[Feed Rate (%)]]/100 -> 1331.1128
A31: B5 | B31: 14 | C31: 4.33 | D31: 3232163 | E31: 18532.23 | F31: =VLOOKUP(T5_Weekly_Feed_Calc[[#This Row],[Sampling ABW (g)]],MAIN!$A$2:$B$10,2,TRUE) -> 7 | G31: =T5_Weekly_Feed_Calc[[#This Row],[Biomass (kg)]]*T5_Weekly_Feed_Calc[[#This Row],[Feed Rate (%)]]/100 -> 1297.2561
A32: C1 | B32: 14 | C32: 6.35 | D32: 2133384 | E32: 25098.94 | F32: =VLOOKUP(T5_Weekly_Feed_Calc[[#This Row],[Sampling ABW (g)]],MAIN!$A$2:$B$10,2,TRUE) -> 5.5 | G32: =T5_Weekly_Feed_Calc[[#This Row],[Biomass (kg)]]*T5_Weekly_Feed_Calc[[#This Row],[Feed Rate (%)]]/100 -> 1380.4417
A33: C2 | B33: 14 | C33: 5.18 | D33: 3344511 | E33: 22299.71 | F33: =VLOOKUP(T5_Weekly_Feed_Calc[[#This Row],[Sampling ABW (g)]],MAIN!$A$2:$B$10,2,TRUE) -> 5.5 | G33: =T5_Weekly_Feed_Calc[[#This Row],[Biomass (kg)]]*T5_Weekly_Feed_Calc[[#This Row],[Feed Rate (%)]]/100 -> 1226.4841
A34: C3 | B34: 14 | C34: 5.81 | D34: 3294426 | E34: 24510.54 | F34: =VLOOKUP(T5_Weekly_Feed_Calc[[#This Row],[Sampling ABW (g)]],MAIN!$A$2:$B$10,2,TRUE) -> 5.5 | G34: =T5_Weekly_Feed_Calc[[#This Row],[Biomass (kg)]]*T5_Weekly_Feed_Calc[[#This Row],[Feed Rate (%)]]/100 -> 1348.0797
... A41: D5 | B41: 14 | C41: 5.66 | D41: 3100549 | E41: 22993.24 | F41: =VLOOKUP(T5_Weekly_Feed_Calc[[#This Row],[Sampling ABW (g)]],MAIN!$A$2:$B$10,2,TRUE) -> 5.5 | G41: =T5_Weekly_Feed_Calc[[#This Row],[Biomass (kg)]]*T5_Weekly_Feed_Calc[[#This Row],[Feed Rate (%)]]/100 -> 1264.6282
A42: A1 | B42: 21 | C42: 6.69 | D42: 3113041 | E42: =T5_Weekly_Feed_Calc[[#This Row],[Pop Count]]*T5_Weekly_Feed_Calc[[#This Row],[Sampling ABW (g)]]/1000 -> 20826.244 | F42: =VLOOKUP(T5_Weekly_Feed_Calc[[#This Row],[Sampling ABW (g)]],MAIN!$A$2:$B$10,2,TRUE) -> 5.5 | G42: =T5_Weekly_Feed_Calc[[#This Row],[Biomass (kg)]]*T5_Weekly_Feed_Calc[[#This Row],[Feed Rate (%)]]/100 -> 1145.4434
A43: A2 | B43: 21 | C43: 6.87 | D43: 3315556 | E43: 29251.38 | F43: =VLOOKUP(T5_Weekly_Feed_Calc[[#This Row],[Sampling ABW (g)]],MAIN!$A$2:$B$10,2,TRUE) -> 5.5 | G43: =T5_Weekly_Feed_Calc[[#This Row],[Biomass (kg)]]*T5_Weekly_Feed_Calc[[#This Row],[Feed Rate (%)]]/100 -> 1608.8259
A44: A3 | B44: 21 | C44: 6.47 | D44: 3228696 | E44: 27385.83 | F44: =VLOOKUP(T5_Weekly_Feed_Calc[[#This Row],[Sampling ABW (g)]],MAIN!$A$2:$B$10,2,TRUE) -> 5.5 | G44: =T5_Weekly_Feed_Calc[[#This Row],[Biomass (kg)]]*T5_Weekly_Feed_Calc[[#This Row],[Feed Rate (%)]]/100 -> 1506.2206
A45: A4 | B45: 21 | C45: 7.49 | D45: 2289333 | E45: 30822.67 | F45: =VLOOKUP(T5_Weekly_Feed_Calc[[#This Row],[Sampling ABW (g)]],MAIN!$A$2:$B$10,2,TRUE) -> 5.5 | G45: =T5_Weekly_Feed_Calc[[#This Row],[Biomass (kg)]]*T5_Weekly_Feed_Calc[[#This Row],[Feed Rate (%)]]/100 -> 1695.2468
A46: A5 | B46: 21 | C46: 7.04 | D46: 3053116 | E46: 27321.9 | F46: =VLOOKUP(T5_Weekly_Feed_Calc[[#This Row],[Sampling ABW (g)]],MAIN!$A$2:$B$10,2,TRUE) -> 5.5 | G46: =T5_Weekly_Feed_Calc[[#This Row],[Biomass (kg)]]*T5_Weekly_Feed_Calc[[#This Row],[Feed Rate (%)]]/100 -> 1502.7045
A47: B1 | B47: 21 | C47: 8.14 | D47: 2017488 | E47: 32146.95 | F47: =VLOOKUP(T5_Weekly_Feed_Calc[[#This Row],[Sampling ABW (g)]],MAIN!$A$2:$B$10,2,TRUE) -> 5.5 | G47: =T5_Weekly_Feed_Calc[[#This Row],[Biomass (kg)]]*T5_Weekly_Feed_Calc[[#This Row],[Feed Rate (%)]]/100 -> 1768.0823
A48: B2 | B48: 21 | C48: 6.34 | D48: 1897271 | E48: 24826.24 | F48: =VLOOKUP(T5_Weekly_Feed_Calc[[#This Row],[Sampling ABW (g)]],MAIN!$A$2:$B$10,2,TRUE) -> 5.5 | G48: =T5_Weekly_Feed_Calc[[#This Row],[Biomass (kg)]]*T5_Weekly_Feed_Calc[[#This Row],[Feed Rate (%)]]/100 -> 1365.4432
A49: B3 | B49: 21 | C49: 7.34 | D49: 2308993 | E49: 31618.3 | F49: =VLOOKUP(T5_Weekly_Feed_Calc[[#This Row],[Sampling ABW (g)]],MAIN!$A$2:$B$10,2,TRUE) -> 5.5 | G49: =T5_Weekly_Feed_Calc[[#This Row],[Biomass (kg)]]*T5_Weekly_Feed_Calc[[#This Row],[Feed Rate (%)]]/100 -> 1739.0065
A50: B4 | B50: 21 | C50: 6.92 | D50: 3172527 | E50: 28056.94 | F50: =VLOOKUP(T5_Weekly_Feed_Calc[[#This Row],[Sampling ABW (g)]],MAIN!$A$2:$B$10,2,TRUE) -> 5.5 | G50: =T5_Weekly_Feed_Calc[[#This Row],[Biomass (kg)]]*T5_Weekly_Feed_Calc[[#This Row],[Feed Rate (%)]]/100 -> 1543.1317
A51: B5 | B51: 21 | C51: 5.86 | D51: 3221662 | E51: 24584.59 | F51: =VLOOKUP(T5_Weekly_Feed_Calc[[#This Row],[Sampling ABW (g)]],MAIN!$A$2:$B$10,2,TRUE) -> 5.5 | G51: =T5_Weekly_Feed_Calc[[#This Row],[Biomass (kg)]]*T5_Weekly_Feed_Calc[[#This Row],[Feed Rate (%)]]/100 -> 1352.1525
A52: C1 | B52: 21 | C52: 7.96 | D52: 2081353 | E52: 30735.37 | F52: =VLOOKUP(T5_Weekly_Feed_Calc[[#This Row],[Sampling ABW (g)]],MAIN!$A$2:$B$10,2,TRUE) -> 5.5 | G52: =T5_Weekly_Feed_Calc[[#This Row],[Biomass (kg)]]*T5_Weekly_Feed_Calc[[#This Row],[Feed Rate (%)]]/100 -> 1690.4453
...
